Workbook

Sheet Data
A1: Order ID | B1: Month | C1: Region | D1: Channel | E1: Category | F1: Product | G1: Salesperson | H1: Quantity | I1: Unit Price (£) | J1: Revenue (£)
A2: 1001 | B2: Feb | C2: South | D2: Online | E2: Electronics | F2: Headphones | G2: Brown | H2: 4 | I2: 169.6 | J2: =H2*I2 -> 678.4
A3: 1002 | B3: Feb | C3: South | D3: Online | E3: Sports | F3: Running Shoes | G3: Davies | H3: 2 | I3: 13.81 | J3: =H3*I3 -> 27.62
A4: 1003 | B4: Mar | C4: North | D4: Online | E4: Sports | F4: Running Shoes | G4: Gupta | H4: 10 | I4: 36.45 | J4: =H4*I4 -> 364.5
A5: 1004 | B5: Jan | C5: North | D5: In-Store | E5: Home | F5: Mug Set | G5: Brown | H5: 6 | I5: 17.64 | J5: =H5*I5 -> 105.84
A6: 1005 | B6: Jun | C6: West | D6: Online | E6: Home | F6: Mug Set | G6: Gupta | H6: 1 | I6: 45.43 | J6: =H6*I6 -> 45.43
A7: 1006 | B7: Mar | C7: South | D7: Online | E7: Electronics | F7: Tablet | G7: Adams | H7: 10 | I7: 186.73 | J7: =H7*I7 -> 1867.3
A8: 1007 | B8: Jan | C8: West | D8: In-Store | E8: Clothing | F8: Jeans | G8: Hughes | H8: 4 | I8: 93.77 | J8: =H8*I8 -> 375.08
A9: 1008 | B9: Jun | C9: East | D9: Online | E9: Home | F9: Cushion | G9: Chen | H9: 4 | I9: 30.95 | J9: =H9*I9 -> 123.8
A10: 1009 | B10: Mar | C10: South | D10: In-Store | E10: Sports | F10: Dumbbells | G10: Adams | H10: 7 | I10: 29.61 | J10: =H10*I10 -> 207.27
A11: 1010 | B11: Mar | C11: North | D11: Online | E11: Clothing | F11: T-Shirt | G11: Flores | H11: 7 | I11: 78.82 | J11: =H11*I11 -> 551.74
A12: 1011 | B12: Apr | C12: South | D12: In-Store | E12: Clothing | F12: Trainers | G12: Chen | H12: 11 | I12: 44.84 | J12: =H12*I12 -> 493.24
A13: 1012 | B13: May | C13: West | D13: In-Store | E13: Clothing | F13: Jeans | G13: Davies | H13: 7 | I13: 74 | J13: =H13*I13 -> 518
... A181: 1180 | B181: May | C181: North | D181: In-Store | E181: Toys | F181: Building Set | G181: Brown | H181: 11 | I181: 36.2 | J181: =H181*I181 -> 398.2

Sheet Exercises
A1: Pivot Table & Function Exercises — Retail Sales
A2: Use the 'Data' sheet. Write your answer (value or formula) in the amber column. Answers are on the 'Answer Key' tab.
C3: Your answer
A5: COUNT — counting rows and values
A6: 1 | B6: How many orders are in the dataset in total? (Hint: COUNT works on numbers — use the Order ID or Quantity column.)
A7: 2 | B7: How many orders have a recorded Unit Price? Use COUNT on the Unit Price column.
A8: COUNTIF — counting with ONE condition
A9: 3 | B9: How many orders were placed in the 'North' region?
A10: 4 | B10: How many orders were in the 'Electronics' category?
A11: 5 | B11: How many orders had a Quantity of 10 or more? (Use the criteria ">=10".)
A12: COUNTIFS — counting with TWO OR MORE conditions
A13: 6 | B13: How many 'Online' orders were placed in the 'South' region?
A14: 7 | B14: How many 'Clothing' orders were sold In-Store?
A15: 8 | B15: How many 'Sports' orders in the 'West' region had a Quantity greater than 5?
A16: SUM — totalling a column
A17: 9 | B17: What is the total Quantity of items sold across all orders?
A18: 10 | B18: What is the total Revenue generated across all orders?
A19: SUMIF — totalling with ONE condition
A20: 11 | B20: What is the total Revenue from the 'Online' channel?
A21: 12 | B21: What is the total Revenue from the 'Home' category?
A22: SUMIFS — totalling with TWO OR MORE conditions
A23: 13 | B23: What is the total Revenue from 'Electronics' sold 'Online'?
A24: 14 | B24: What is the total Revenue from the 'East' region in the 'In-Store' channel?
A25: 15 | B25: What is the total Quantity of 'Toys' sold by the salesperson 'Chen'?
A26: AVERAGE — the mean of a column
A27: 16 | B27: What is the average Unit Price across all orders?
A28: 17 | B28: What is the average Revenue per order?
A29: AVERAGEIF — the mean with ONE condition
A30: 18 | B30: What is the average Revenue of 'Online' orders?
A31: 19 | B31: What is the average Unit Price in the 'Electronics' category?
A32: AVERAGEIFS — the mean with TWO OR MORE conditions
A33: 20 | B33: What is the average Revenue for 'Clothing' orders sold 'Online'?
A34: 21 | B34: What is the average Quantity for 'Sports' orders in the 'North' region?
A35: STANDARD DEVIATION — spread of the data
A36: 22 | B36: What is the standard deviation of Unit Price across all orders? (Treat the data as the whole population — use STDEV.P.)
A37: 23 | B37: What is the sample standard deviation of Revenue? (Use STDEV.S.)
A38: 24 | B38: Which has more variability relative to its mean — Quantity or Unit Price? (Compare each standard deviation ÷ its average; the higher ratio is more variable.)
A39: PIVOT TABLES & DASHBOARD — bring it together
A40: 25 | B40: Insert a PivotTable from the Data sheet. Put Category in Rows and Sum of Revenue in Values. Which category earns the most revenue?
A41: 26 | B41: Change the pivot to show Region in Rows and Channel in Columns, with Sum of Revenue as values. Which Region/Channel combination is strongest?
...

Sheet Answer Key
A1: Answer Key — formulas recalculate live from the Data sheet
A3: # | B3: Formula (paste into any blank cell) | C3: Function | D3: Result
A4: 1 | B4: '=COUNT(Data!$A$2:$A$181) | C4: COUNT | D4: =COUNT(Data!$A$2:$A$181) -> 180
A5: 2 | B5: '=COUNT(Data!$I$2:$I$181) | C5: COUNT | D5: =COUNT(Data!$I$2:$I$181) -> 180
A6: 3 | B6: '=COUNTIF(Data!$C$2:$C$181,"North") | C6: COUNTIF | D6: =COUNTIF(Data!$C$2:$C$181,"North") -> 47
A7: 4 | B7: '=COUNTIF(Data!$E$2:$E$181,"Electronics") | C7: COUNTIF | D7: =COUNTIF(Data!$E$2:$E$181,"Electronics") -> 37
A8: 5 | B8: '=COUNTIF(Data!$H$2:$H$181,">=10") | C8: COUNTIF | D8: =COUNTIF(Data!$H$2:$H$181,">=10") -> 47
A9: 6 | B9: '=COUNTIFS(Data!$D$2:$D$181,"Online",Data!$C$2:$C$181,"South") | C9: COUNTIFS | D9: =COUNTIFS(Data!$D$2:$D$181,"Online",Data!$C$2:$C$181,"South") -> 27
A10: 7 | B10: '=COUNTIFS(Data!$E$2:$E$181,"Clothing",Data!$D$2:$D$181,"In-Store") | C10: COUNTIFS | D10: =COUNTIFS(Data!$E$2:$E$181,"Clothing",Data!$D$2:$D$181,"In-Store") -> 10
A11: 8 | B11: '=COUNTIFS(Data!$E$2:$E$181,"Sports",Data!$C$2:$C$181,"West",Data!$H$2:$H$181,">5") | C11: COUNTIFS | D11: =COUNTIFS(Data!$E$2:$E$181,"Sports",Data!$C$2:$C$181,"West",Data!$H$2:$H$181,">5") -> 3
A12: 9 | B12: '=SUM(Data!$H$2:$H$181) | C12: SUM | D12: =SUM(Data!$H$2:$H$181) -> 1202
A13: 10 | B13: '=SUM(Data!$J$2:$J$181) | C13: SUM | D13: =SUM(Data!$J$2:$J$181) -> 77262.17
A14: 11 | B14: '=SUMIF(Data!$D$2:$D$181,"Online",Data!$J$2:$J$181) | C14: SUMIF | D14: =SUMIF(Data!$D$2:$D$181,"Online",Data!$J$2:$J$181) -> 38903.92
A15: 12 | B15: '=SUMIF(Data!$E$2:$E$181,"Home",Data!$J$2:$J$181) | C15: SUMIF | D15: =SUMIF(Data!$E$2:$E$181,"Home",Data!$J$2:$J$181) -> 10758.84
A16: 13 | B16: '=SUMIFS(Data!$J$2:$J$181,Data!$E$2:$E$181,"Electronics",Data!$D$2:$D$181,"Online") | C16: SUMIFS | D16: =SUMIFS(Data!$J$2:$J$181,Data!$E$2:$E$181,"Electronics",Data!$D$2:$D$181,"Online") -> 14975
A17: 14 | B17: '=SUMIFS(Data!$J$2:$J$181,Data!$C$2:$C$181,"East",Data!$D$2:$D$181,"In-Store") | C17: SUMIFS | D17: =SUMIFS(Data!$J$2:$J$181,Data!$C$2:$C$181,"East",Data!$D$2:$D$181,"In-Store") -> 7159.25
A18: 15 | B18: '=SUMIFS(Data!$H$2:$H$181,Data!$E$2:$E$181,"Toys",Data!$G$2:$G$181,"Chen") | C18: SUMIFS | D18: =SUMIFS(Data!$H$2:$H$181,Data!$E$2:$E$181,"Toys",Data!$G$2:$G$181,"Chen") -> 25
A19: 16 | B19: '=AVERAGE(Data!$I$2:$I$181) | C19: AVERAGE | D19: =AVERAGE(Data!$I$2:$I$181) -> 62.383222
A20: 17 | B20: '=AVERAGE(Data!$J$2:$J$181) | C20: AVERAGE | D20: =AVERAGE(Data!$J$2:$J$181) -> 429.23428
A21: 18 | B21: '=AVERAGEIF(Data!$D$2:$D$181,"Online",Data!$J$2:$J$181) | C21: AVERAGEIF | D21: =AVERAGEIF(Data!$D$2:$D$181,"Online",Data!$J$2:$J$181) -> 452.37116
A22: 19 | B22: '=AVERAGEIF(Data!$E$2:$E$181,"Electronics",Data!$I$2:$I$181) | C22: AVERAGEIF | D22: =AVERAGEIF(Data!$E$2:$E$181,"Electronics",Data!$I$2:$I$181) -> 121.76595
A23: 20 | B23: '=AVERAGEIFS(Data!$J$2:$J$181,Data!$E$2:$E$181,"Clothing",Data!$D$2:$D$181,"Online") | C23: AVERAGEIFS | D23: =AVERAGEIFS(Data!$J$2:$J$181,Data!$E$2:$E$181,"Clothing",Data!$D$2:$D$181,"Online") -> 371.32579
A24: 21 | B24: '=AVERAGEIFS(Data!$H$2:$H$181,Data!$E$2:$E$181,"Sports",Data!$C$2:$C$181,"North") | C24: AVERAGEIFS | D24: =AVERAGEIFS(Data!$H$2:$H$181,Data!$E$2:$E$181,"Sports",Data!$C$2:$C$181,"North") -> 7
A25: 22 | B25: '=STDEV.P(Data!$I$2:$I$181) | C25: STDEV.P | D25: =_xlfn.STDEV.P(Data!$I$2:$I$181) -> 47.771801
A26: 23 | B26: '=STDEV.S(Data!$J$2:$J$181) | C26: STDEV.S | D26: =_xlfn.STDEV.S(Data!$J$2:$J$181) -> 420.04077
A27: 24 | B27: '=STDEV.P(Data!$H$2:$H$181)/AVERAGE(Data!$H$2:$H$181) | C27: STDEV/AVG | D27: =_xlfn.STDEV.P(Data!$H$2:$H$181)/AVERAGE(Data!$H$2:$H$181) -> 0.51505232
B28: (For Q24, also compute Unit Price ratio below and compare — the larger ratio = more variable.) | C28: STDEV/AVG | D28: =_xlfn.STDEV.P(Data!$I$2:$I$181)/AVERAGE(Data!$I$2:$I$181) -> 0.76577963
A30: Q25–29 — Pivot table & dashboard tasks (guidance, not single values)
A31: Q25 Insert > PivotTable. Category → Rows, Revenue → Values (Sum). The category with the tallest total is the answer; it will recalc from the data.
A32: Q26 Region → Rows, Channel → Columns, Revenue → Values. Read the largest cell in the grid for the strongest Region×Channel combo.
A33: Q27 Salesperson → Rows; add Revenue (Sum) AND Order ID (Count) to Values. Add a calculated measure or a side column = Revenue/Count for revenue per order.
A34: Q28 Two charts (Revenue by Month, Revenue by Category) + Insert > Slicer > Region. Clicking 'North' filters BOTH charts to North only — they shrink/refilter together.
A35: Q29 COUNTIFS result (Q13 logic with count) must equal the pivot's Count for Online+Electronics. If they differ, a filter or range is wrong.
